Workbook

Sheet Run Overview
B2: GO Website Manual QA 1.9
B3: Prepared 28 October 2026. New results have not been executed.
B5: Current run | F5: Run details to complete
B6: Total cases | C6: =COUNTA('V 1.9 TEST'!$B$2:$B$1000) -> 674 | F6: Test environment | G6: To complete
B7: Pass | C7: =COUNTIFS('V 1.9 TEST'!$A$2:$A$1000,"Pass",'V 1.9 TEST'!$B$2:$B$1000,"<>") -> 0 | F7: Base URL
B8: Fail | C8: =COUNTIFS('V 1.9 TEST'!$A$2:$A$1000,"Fail",'V 1.9 TEST'!$B$2:$B$1000,"<>") -> 0 | F8: Deployed build / commit
B9: Blocked | C9: =COUNTIFS('V 1.9 TEST'!$A$2:$A$1000,"Blocked",'V 1.9 TEST'!$B$2:$B$1000,"<>") -> 0 | F9: Tester / lead
B10: Retest | C10: =COUNTIFS('V 1.9 TEST'!$A$2:$A$1000,"Retest",'V 1.9 TEST'!$B$2:$B$1000,"<>") -> 0 | F10: Run started
B11: Not Run | C11: =COUNTIFS('V 1.9 TEST'!$A$2:$A$1000,"Not Run",'V 1.9 TEST'!$B$2:$B$1000,"<>") -> 674 | F11: Run finished
B12: N/A | C12: =COUNTIFS('V 1.9 TEST'!$A$2:$A$1000,"N/A",'V 1.9 TEST'!$B$2:$B$1000,"<>") -> 0 | F12: Primary browser / version
B13: Executed (Pass + Fail) | C13: =SUM(C7:C8) -> 0 | F13: Secondary browser / device
B14: Execution coverage | C14: =IF(C6-C12=0,0,C13/(C6-C12)) -> 0 | F14: Functional review decision | G14: Not reviewed
B15: Pass rate of executed | C15: =IF(C13=0,"n.a.",C7/C13) -> n.a.
B16: Unrecognized / blank status | C16: =C6-SUM(C7:C12) -> 0
B18: Functional completion | F18: Run order
B19: Applicable functional cases | C19: =COUNTIFS('V 1.9 TEST'!$B$2:$B$1000,"<>",'V 1.9 TEST'!$J$2:$J$1000,"<>Visual",'V 1.9 TEST'!$A$2:$A$1000,"<>N/A") -> 629 | F19: 1. Prepare | G19: Enter URL/build, accounts and effective flags. Do not copy passwords or tokens into this workbook.
B20: Functional Pass | C20: =COUNTIFS('V 1.9 TEST'!$B$2:$B$1000,"<>",'V 1.9 TEST'!$J$2:$J$1000,"<>Visual",'V 1.9 TEST'!$A$2:$A$1000,"Pass") -> 0 | F20: 2. Smoke | G20: Filter Run Set = Smoke. Run the critical end-to-end journeys first.
B21: Functional checks remaining | C21: =C19-C20 -> 629 | F21: 3. Regression | G21: Run current in-scope regression cases by suite and persona. Then run Extended integration checks.
B22: P0 Fail / Blocked / Retest | C22: =COUNTIFS('V 1.9 TEST'!$G$2:$G$1000,"P0",'V 1.9 TEST'!$A$2:$A$1000,"Fail")+COUNTIFS('V 1.9 TEST'!$G$2:$G$1000,"P0",'V 1.9 TEST'!$A$2:$A$1000,"Blocked")+COUNTIFS('V 1.9 TEST'!$G$2:$G$1000,"P0",'V 1.9 TEST'!$A$2:$A$1000,"Retest") -> 0 | F22: 4. Record | G22: Use Status, Actual Result, Notes, Evidence Link, date, tester, browser/viewport and Issue Link.
B23: Run state | C23: =IF(OR(G7="",G8=""),"Record URL and build",IF(C16<>0,"Check status entries",IF(C21>0,"Testing incomplete",IF(G14<>"Approved","Review required","Functional review approved")))) -> Record URL and build | F23: 5. Retest | G23: Filter Previous Status for Retest, Fail or Blocked. Historical status is context and never a current pass.
F24: 6. Visual | G24: Capture current appearance, accessibility and motion after functionality. Log later cosmetic work in UX Backlog.
B27: Coverage by suite
B28: Suite | C28: Total | D28: Pass | F28: Fail | G28: Blocked | H28: Remaining
B29: Public Website | C29: =COUNTIFS('V 1.9 TEST'!$C$2:$C$1000,B29) -> 10 | D29: =COUNTIFS('V 1.9 TEST'!$C$2:$C$1000,B29,'V 1.9 TEST'!$A$2:$A$1000,"Pass") -> 0 | F29: =COUNTIFS('V 1.9 TEST'!$C$2:$C$1000,B29,'V 1.9 TEST'!$A$2:$A$1000,"Fail") -> 0 | G29: =COUNTIFS('V 1.9 TEST'!$C$2:$C$1000,B29,'V 1.9 TEST'!$A$2:$A$1000,"Blocked") -> 0 | H29: =C29-D29-COUNTIFS('V 1.9 TEST'!$C$2:$C$1000,B29,'V 1.9 TEST'!$A$2:$A$1000,"N/A") -> 10
B30: Auth | C30: =COUNTIFS('V 1.9 TEST'!$C$2:$C$1000,B30) -> 7 | D30: =COUNTIFS('V 1.9 TEST'!$C$2:$C$1000,B30,'V 1.9 TEST'!$A$2:$A$1000,"Pass") -> 0 | F30: =COUNTIFS('V 1.9 TEST'!$C$2:$C$1000,B30,'V 1.9 TEST'!$A$2:$A$1000,"Fail") -> 0 | G30: =COUNTIFS('V 1.9 TEST'!$C$2:$C$1000,B30,'V 1.9 TEST'!$A$2:$A$1000,"Blocked") -> 0 | H30: =C30-D30-COUNTIFS('V 1.9 TEST'!$C$2:$C$1000,B30,'V 1.9 TEST'!$A$2:$A$1000,"N/A") -> 7
B31: Onboarding | C31: =COUNTIFS('V 1.9 TEST'!$C$2:$C$1000,B31) -> 5 | D31: =COUNTIFS('V 1.9 TEST'!$C$2:$C$1000,B31,'V 1.9 TEST'!$A$2:$A$1000,"Pass") -> 0 | F31: =COUNTIFS('V 1.9 TEST'!$C$2:$C$1000,B31,'V 1.9 TEST'!$A$2:$A$1000,"Fail") -> 0 | G31: =COUNTIFS('V 1.9 TEST'!$C$2:$C$1000,B31,'V 1.9 TEST'!$A$2:$A$1000,"Blocked") -> 0 | H31: =C31-D31-COUNTIFS('V 1.9 TEST'!$C$2:$C$1000,B31,'V 1.9 TEST'!$A$2:$A$1000,"N/A") -> 5
B32: Profile | C32: =COUNTIFS('V 1.9 TEST'!$C$2:$C$1000,B32) -> 4 | D32: =COUNTIFS('V 1.9 TEST'!$C$2:$C$1000,B32,'V 1.9 TEST'!$A$2:$A$1000,"Pass") -> 0 | F32: =COUNTIFS('V 1.9 TEST'!$C$2:$C$1000,B32,'V 1.9 TEST'!$A$2:$A$1000,"Fail") -> 0 | G32: =COUNTIFS('V 1.9 TEST'!$C$2:$C$1000,B32,'V 1.9 TEST'!$A$2:$A$1000,"Blocked") -> 0 | H32: =C32-D32-COUNTIFS('V 1.9 TEST'!$C$2:$C$1000,B32,'V 1.9 TEST'!$A$2:$A$1000,"N/A") -> 4
B33: CV | C33: =COUNTIFS('V 1.9 TEST'!$C$2:$C$1000,B33) -> 6 | D33: =COUNTIFS('V 1.9 TEST'!$C$2:$C$1000,B33,'V 1.9 TEST'!$A$2:$A$1000,"Pass") -> 0 | F33: =COUNTIFS('V 1.9 TEST'!$C$2:$C$1000,B33,'V 1.9 TEST'!$A$2:$A$1000,"Fail") -> 0 | G33: =COUNTIFS('V 1.9 TEST'!$C$2:$C$1000,B33,'V 1.9 TEST'!$A$2:$A$1000,"Blocked") -> 0 | H33: =C33-D33-COUNTIFS('V 1.9 TEST'!$C$2:$C$1000,B33,'V 1.9 TEST'!$A$2:$A$1000,"N/A") -> 6
B34: Projects | C34: =COUNTIFS('V 1.9 TEST'!$C$2:$C$1000,B34) -> 17 | D34: =COUNTIFS('V 1.9 TEST'!$C$2:$C$1000,B34,'V 1.9 TEST'!$A$2:$A$1000,"Pass") -> 0 | F34: =COUNTIFS('V 1.9 TEST'!$C$2:$C$1000,B34,'V 1.9 TEST'!$A$2:$A$1000,"Fail") -> 0 | G34: =COUNTIFS('V 1.9 TEST'!$C$2:$C$1000,B34,'V 1.9 TEST'!$A$2:$A$1000,"Blocked") -> 0 | H34: =C34-D34-COUNTIFS('V 1.9 TEST'!$C$2:$C$1000,B34,'V 1.9 TEST'!$A$2:$A$1000,"N/A") -> 17
B35: Applications | C35: =COUNTIFS('V 1.9 TEST'!$C$2:$C$1000,B35) -> 11 | D35: =COUNTIFS('V 1.9 TEST'!$C$2:$C$1000,B35,'V 1.9 TEST'!$A$2:$A$1000,"Pass") -> 0 | F35: =COUNTIFS('V 1.9 TEST'!$C$2:$C$1000,B35,'V 1.9 TEST'!$A$2:$A$1000,"Fail") -> 0 | G35: =COUNTIFS('V 1.9 TEST'!$C$2:$C$1000,B35,'V 1.9 TEST'!$A$2:$A$1000,"Blocked") -> 0 | H35: =C35-D35-COUNTIFS('V 1.9 TEST'!$C$2:$C$1000,B35,'V 1.9 TEST'!$A$2:$A$1000,"N/A") -> 11
B36: Admin | C36: =COUNTIFS('V 1.9 TEST'!$C$2:$C$1000,B36) -> 6 | D36: =COUNTIFS('V 1.9 TEST'!$C$2:$C$1000,B36,'V 1.9 TEST'!$A$2:$A$1000,"Pass") -> 0 | F36: =COUNTIFS('V 1.9 TEST'!$C$2:$C$1000,B36,'V 1.9 TEST'!$A$2:$A$1000,"Fail") -> 0 | G36: =COUNTIFS('V 1.9 TEST'!$C$2:$C$1000,B36,'V 1.9 TEST'!$A$2:$A$1000,"Blocked") -> 0 | H36: =C36-D36-COUNTIFS('V 1.9 TEST'!$C$2:$C$1000,B36,'V 1.9 TEST'!$A$2:$A$1000,"N/A") -> 6
B37: Billing | C37: =COUNTIFS('V 1.9 TEST'!$C$2:$C$1000,B37) -> 17 | D37: =COUNTIFS('V 1.9 TEST'!$C$2:$C$1000,B37,'V 1.9 TEST'!$A$2:$A$1000,"Pass") -> 0 | F37: =COUNTIFS('V 1.9 TEST'!$C$2:$C$1000,B37,'V 1.9 TEST'!$A$2:$A$1000,"Fail") -> 0 | G37: =COUNTIFS('V 1.9 TEST'!$C$2:$C$1000,B37,'V 1.9 TEST'!$A$2:$A$1000,"Blocked") -> 0 | H37: =C37-D37-COUNTIFS('V 1.9 TEST'!$C$2:$C$1000,B37,'V 1.9 TEST'!$A$2:$A$1000,"N/A") -> 17
B38: Firestore Rules | C38: =COUNTIFS('V 1.9 TEST'!$C$2:$C$1000,B38) -> 7 | D38: =COUNTIFS('V 1.9 TEST'!$C$2:$C$1000,B38,'V 1.9 TEST'!$A$2:$A$1000,"Pass") -> 0 | F38: =COUNTIFS('V 1.9 TEST'!$C$2:$C$1000,B38,'V 1.9 TEST'!$A$2:$A$1000,"Fail") -> 0 | G38: =COUNTIFS('V 1.9 TEST'!$C$2:$C$1000,B38,'V 1.9 TEST'!$A$2:$A$1000,"Blocked") -> 0 | H38: =C38-D38-COUNTIFS('V 1.9 TEST'!$C$2:$C$1000,B38,'V 1.9 TEST'!$A$2:$A$1000,"N/A") -> 7
B39: UX | C39: =COUNTIFS('V 1.9 TEST'!$C$2:$C$1000,B39) -> 8 | D39: =COUNTIFS('V 1.9 TEST'!$C$2:$C$1000,B39,'V 1.9 TEST'!$A$2:$A$1000,"Pass") -> 0 | F39: =COUNTIFS('V 1.9 TEST'!$C$2:$C$1000,B39,'V 1.9 TEST'!$A$2:$A$1000,"Fail") -> 0 | G39: =COUNTIFS('V 1.9 TEST'!$C$2:$C$1000,B39,'V 1.9 TEST'!$A$2:$A$1000,"Blocked") -> 0 | H39: =C39-D39-COUNTIFS('V 1.9 TEST'!$C$2:$C$1000,B39,'V 1.9 TEST'!$A$2:$A$1000,"N/A") -> 8
B40: Release | C40: =COUNTIFS('V 1.9 TEST'!$C$2:$C$1000,B40) -> 2 | D40: =COUNTIFS('V 1.9 TEST'!$C$2:$C$1000,B40,'V 1.9 TEST'!$A$2:$A$1000,"Pass") -> 0 | F40: =COUNTIFS('V 1.9 TEST'!$C$2:$C$1000,B40,'V 1.9 TEST'!$A$2:$A$1000,"Fail") -> 0 | G40: =COUNTIFS('V 1.9 TEST'!$C$2:$C$1000,B40,'V 1.9 TEST'!$A$2:$A$1000,"Blocked") -> 0 | H40: =C40-D40-COUNTIFS('V 1.9 TEST'!$C$2:$C$1000,B40,'V 1.9 TEST'!$A$2:$A$1000,"N/A") -> 2
... B70: Baseline & Recovery | C70: =COUNTIFS('V 1.9 TEST'!$C$2:$C$1000,B70) -> 5 | D70: =COUNTIFS('V 1.9 TEST'!$C$2:$C$1000,B70,'V 1.9 TEST'!$A$2:$A$1000,"Pass") -> 0 | F70: =COUNTIFS('V 1.9 TEST'!$C$2:$C$1000,B70,'V 1.9 TEST'!$A$2:$A$1000,"Fail") -> 0 | G70: =COUNTIFS('V 1.9 TEST'!$C$2:$C$1000,B70,'V 1.9 TEST'!$A$2:$A$1000,"Blocked") -> 0 | H70: =C70-D70-COUNTIFS('V 1.9 TEST'!$C$2:$C$1000,B70,'V 1.9 TEST'!$A$2:$A$1000,"N/A") -> 5
B73: Run conventions
B74: Statuses | C74: Not Run: untouched. Pass: observed expected result. Fail: observed defect. Blocked: prerequisite unavailable. Retest: fix awaits verification. N/A: deliberately outside this run; explain why in Notes.
B75: Priorities | C75: P0: critical flow, privacy, entitlement or data integrity. P1: normal functional behavior. P2: lower-impact presentation or refinement. These priorities order this test run.
B76: Scope | C76: Record actual flags below. Enabled but unusable because data, credentials or an index is missing = Blocked. Intentionally disabled/out-of-scope = N/A with a reason. Exercise disabled-state checks as well.
...

Sheet V 1.9 TEST
A1: Status | B1: Test ID | C1: Suite | D1: Steps | E1: Expected Result | F1: Feature | G1: Priority | H1: Persona | I1: Preconditions | J1: Run Set | K1: Actual Result | L1: Notes | M1: Evidence Link | N1: Run Date | O1: Tester | P1: Browser / Viewport | Q1: Issue Link | R1: Scope / Feature Flag | S1: Previous Status | T1: Previous Notes / Source | U1: Change
A2: Not Run | B2: GO-MAN-001 | C2: Public Website | D2: Open the home page; wait for the page to fully load; check above-the-fold content; scroll to bottom | E2: Home page loads without console-visible broken UI; main brand/content is clear; no missing critical images; footer is reachable | F2: Home page load | G2: P0 | H2: Visitor | I2: Production or local site is running | J2: Smoke | R2: Core | S2: Not Run | T2: V 1.7 TEST: Functionally clean, however there are multiple improvements to be made on the Landing Page Bugs will be reported | U2: Retained
A3: Not Run | B3: GO-MAN-002 | C3: Public Website | D3: Open home page; click each main nav item; use browser back; repeat for logo/home link | E3: Every nav item routes to the expected page; no 404; active page content matches navigation label | F3: Desktop navigation | G3: P0 | H3: Visitor | I3: Site is running on desktop viewport | J3: Smoke | R3: Core | S3: Not Run | U3: Retained
A4: Not Run | B4: GO-MAN-003 | C4: Public Website | D4: Resize to mobile or use phone; open mobile menu; tap every nav item; close and reopen menu | E4: Mobile menu is usable; links work; menu does not overlap content; menu can be dismissed | F4: Mobile navigation | G4: P0 | H4: Visitor | I4: Site is running on mobile viewport | J4: Smoke | R4: Core | S4: Not Run | U4: Retained
A5: Not Run | B5: GO-MAN-004 | C5: Public Website | D5: Open home page; click primary CTA; return; click secondary CTAs; check destination pages | E5: CTAs route to intended signup/pricing/contact/project pages; labels match destination intent | F5: Landing CTAs | G5: P0 | H5: Visitor | I5: Site is running | J5: Regression | R5: Core | S5: Not Run | U5: Retained
A6: Not Run | B6: GO-MAN-005 | C6: Public Website | D6: Check home/pricing/projects/about/FAQ pages at 390px 768px and desktop widths | E6: No horizontal scrolling; text does not overlap; buttons fit; sections remain readable | F6: Responsive layout | G6: P1 | H6: Visitor | I6: Use desktop tablet and mobile widths | J6: Regression | R6: Core | S6: Not Run | U6: Retained
A7: Not Run | B7: GO-MAN-006 | C7: Public Website | D7: Open key public pages; look for broken images/icons; refresh once | E7: Images/icons render correctly; no obvious layout jumps due to missing assets | F7: Image and asset loading | G7: P1 | H7: Visitor | I7: Site is running | J7: Regression | R7: Core | S7: Not Run | U7: Retained
A8: Not Run | B8: GO-MAN-007 | C8: Public Website | D8: Open FAQ; expand/collapse each FAQ item; check links if present | E8: FAQ controls work; content is readable; links open expected destinations | F8: FAQ page | G8: P1 | H8: Visitor | I8: FAQ page exists | J8: Regression | R8: Core | S8: Retest | T8: V 1.7 TEST: Functionality is there but test is failed but the information is innacurate, we need to update the FAQ to reflect the real business proposition we are offering | U8: Retained
A9: Not Run | B9: GO-MAN-008 | C9: Public Website | D9: Open About; scan page content; test visible links/buttons | E9: About content is readable and current; links/buttons work; no typo-heavy or placeholder content | F9: About page | G9: P1 | H9: Visitor | I9: About page exists | J9: Regression | R9: Core | S9: Retest | T9: V 1.7 TEST: Functionality is there but test is failed but the information is innacurate, we need to update the ABOIT US to reflect the real business proposition we are offering | U9: Retained
A10: Not Run | B10: GO-MAN-009 | C10: Public Website | D10: Open pricing page; inspect all tiers and intervals; toggle monthly/annual if available | E10: Pricing is understandable; member vs company benefits are clear; checkout buttons are visible | F10: Pricing page | G10: P0 | H10: Visitor | I10: Polar products configured | J10: Smoke | R10: Core | S10: Not Run | T10: V 1.7 TEST: We offer a community newsletter but we don't have one. See what we need in order to have one. | U10: Retained
A11: Not Run | B11: GO-MAN-010 | C11: Public Website | D11: Open a nonsense URL such as /this-page-does-not-exist | E11: User sees a graceful not-found or redirect experience; no raw error stack | F11: 404/not-found experience | G11: P2 | H11: Visitor | I11: Site is running | J11: Regression | R11: Core | S11: Not Run | U11: Retained
A12: Not Run | B12: GO-MAN-011 | C12: Auth | D12: Open signup; create account; complete required fields; submit | E12: Account is created; user lands on expected next page; no duplicate or confusing messages | F12: Signup flow | G12: P0 | H12: Visitor | I12: Test email available | J12: Smoke | R12: Core | S12: Not Run | U12: Retained
A13: Not Run | B13: GO-MAN-012 | C13: Auth | D13: Open login; enter valid credentials; submit | E13: User logs in; protected nav/profile state appears; no unexpected redirect loop | F13: Login flow | G13: P0 | H13: Free User | I13: Existing account available | J13: Smoke | R13: Core | S13: Not Run | U13: Retained
A14: Not Run | B14: GO-MAN-013 | C14: Auth | D14: Enter invalid credentials; submit | E14: Clear error appears; password is not exposed; form remains usable | F14: Invalid login | G14: P1 | H14: Visitor | I14: Login page available | J14: Regression | R14: Core | S14: Not Run | U14: Retained
A15: Not Run | B15: GO-MAN-014 | C15: Auth | D15: Use profile/menu logout action; confirm logged-out state | E15: Session ends; protected links redirect or hide; public pages still work | F15: Logout flow | G15: P0 | H15: Logged-in User | I15: User is logged in | J15: Smoke | R15: Core | S15: Not Run | U15: Retained
A16: Not Run | B16: GO-MAN-015 | C16: Auth | D16: Open reset password; enter test account email; submit | E16: User receives success state; reset email is sent if email service is configured | F16: Password reset | G16: P1 | H16: Visitor | I16: Reset password page and email service configured | J16: Regression | R16: Core | S16: Retest | T16: V 1.7 TEST: Reset password throrws error Failed to send reset email. Please try again | U16: Retained
A17: Not Run | B17: GO-MAN-016 | C17: Auth | D17: Open /dashboard /billing /admin /project/create directly | E17: Logged-out visitor is redirected or shown auth-required state; no protected data is visible | F17: Protected route redirect | G17: P0 | H17: Visitor | I17: Logged out | J17: Smoke | R17: Core | S17: Not Run | U17: Retained
A18: Not Run | B18: GO-MAN-017 | C18: Auth | D18: Refresh current page; close and reopen browser tab; revisit site | E18: Session remains valid if expected; user identity and nav state are stable | F18: Session persistence | G18: P1 | H18: Logged-in User | I18: User is logged in | J18: Regression | R18: Core | S18: Not Run | U18: Retained
A19: Not Run | B19: GO-MAN-018 | C19: Onboarding | D19: Open onboarding page; begin onboarding flow | E19: Onboarding starts cleanly; first step is clear; progress is visible if expected | F19: Start onboarding | G19: P0 | H19: Logged-in User | I19: Logged in as member | J19: Regression | R19: Core | S19: Not Run | U19: Retained
A20: Not Run | B20: GO-MAN-019 | C20: Onboarding | D20: Complete every required onboarding step with valid values; submit final step | E20: Profile is saved; completion state appears; user can proceed to CV generation | F20: Complete required fields | G20: P0 | H20: Logged-in User | I20: Onboarding available | J20: Smoke | R20: Core | S20: Not Run | U20: Retained
A21: Not Run | B21: GO-MAN-020 | C21: Onboarding | D21: Leave required fields empty; enter invalid URLs; exceed long text limits; submit | E21: Helpful validation errors appear; entered valid data is preserved; user can correct and continue | F21: Validation errors | G21: P1 | H21: Logged-in User | I21: Onboarding available | J21: Regression | R21: Core | S21: Not Run | U21: Retained
A22: Not Run | B22: GO-MAN-021 | C22: Onboarding | D22: Move forward several steps; go back; edit previous values; move forward again | E22: Previously entered values persist; progress remains correct; no data loss | F22: Back/forward navigation | G22: P1 | H22: Logged-in User | I22: Onboarding in progress | J22: Regression | R22: Core | S22: Not Run | U22: Retained
A23: Not Run | B23: GO-MAN-022 | C23: Onboarding | D23: Complete onboarding on mobile viewport | E23: Controls are tappable; inputs fit screen; progress and buttons remain visible | F23: Mobile onboarding | G23: P1 | H23: Logged-in User | I23: Mobile viewport | J23: Regression | R23: Core | S23: Not Run | U23: Retained
A24: Not Run | B24: GO-MAN-023 | C24: Profile | D24: Open profile page; inspect displayed fields | E24: Profile displays current user data; no private admin-only fields are shown | F24: View own profile | G24: P0 | H24: Logged-in User | I24: Profile data exists | J24: Regression | R24: Core | S24: Not Run | U24: Retained
A25: Not Run | B25: GO-MAN-024 | C25: Profile | D25: Edit display name role tools portfolio links and visibility settings; save | E25: Changes save successfully and persist after refresh | F25: Edit profile | G25: P0 | H25: Logged-in User | I25: Profile page available | J25: Smoke | R25: Core | S25: Not Run | U25: Retained
A26: Not Run | B26: GO-MAN-025 | C26: Profile | D26: Enter social/portfolio URL without http/https; save | E26: Validation error appears; invalid URL is not silently accepted | F26: Profile invalid social URL | G26: P1 | H26: Logged-in User | I26: Profile editor available | J26: Regression | R26: Core | S26: Not Run | U26: Retained
A27: Not Run | B27: GO-MAN-026 | C27: Profile | D27: Toggle public/private or visibility settings; save; view from another account if possible | E27: Visibility settings persist and affect what other users can see | F27: Privacy settings | G27: P1 | H27: Logged-in User | I27: Profile editor available | J27: Regression | R27: Core | S27: Not Run | U27: Retained
A28: Not Run | B28: GO-MAN-027 | C28: CV | D28: Open CV page; click generate; wait for result | E28: CV is generated from profile data; title summary sections appear; no invented facts are obvious | F28: Generate CV | G28: P0 | H28: Logged-in User | I28: Onboarding profile completed | J28: Smoke | R28: Core | S28: Not Run | U28: Retained
A29: Not Run | B29: GO-MAN-028 | C29: CV | D29: Generate a Passport from a completed onboarding profile without any AI service configured. Refresh it. | E29: Generation succeeds using stored profile facts. No AI key or AI consent is required. | F29: Passport generation without AI | G29: P1 | H29: Logged-in User | I29: AI key disabled or unavailable in test env | J29: Regression | R29: Core | S29: Retest | T29: V 1.7 TEST: We will not be using AI for creation and updates of CV at the moment maybe in the future, all mentions for AI being used or consent formes need to be removed. | U29: Updated
A30: Not Run | B30: GO-MAN-029 | C30: CV | D30: Edit CV title summary and at least one section; save | E30: Edits persist after refresh; formatting remains readable | F30: Edit CV | G30: P0 | H30: Logged-in User | I30: CV exists | J30: Regression | R30: Core | S30: Not Run | U30: Retained
A31: Not Run | B31: GO-MAN-030 | C31: CV | D31: Click publish/approve; confirm if prompted | E31: CV status becomes active/published; user receives clear success state | F31: Publish CV | G31: P0 | H31: Logged-in User | I31: Draft CV exists | J31: Smoke | R31: Core | S31: Not Run | U31: Retained
A32: Not Run | B32: GO-MAN-031 | C32: CV | D32: Change CV visibility settings; view user/project application context from another account | E32: CV is visible only where expected based on settings | F32: CV visibility | G32: P1 | H32: Logged-in User | I32: CV exists and second account available | J32: Regression | R32: Core | S32: Not Run | U32: Retained
A33: Not Run | B33: GO-MAN-032 | C33: CV | D33: Open CV page; edit and publish on mobile | E33: CV editor and publish controls are usable; no clipped text/buttons | F33: CV mobile usability | G33: P1 | H33: Logged-in User | I33: Mobile viewport | J33: Regression | R33: Core | S33: Not Run | U33: Retained
A34: Not Run | B34: GO-MAN-033 | C34: Projects | D34: Open /projects while logged out; inspect visible projects | E34: Visitor sees only public discoverable projects; no private/draft/pending projects appear | F34: Project listing visitor | G34: P0 | H34: Visitor | I34: Projects exist with different statuses/visibility | J34: Smoke | R34: Core | S34: Not Run | U34: Retained
A35: Not Run | B35: GO-MAN-034 | C35: Projects | D35: Open a public project detail page | E35: Project detail loads; visible fields are appropriate for visitor; apply controls require login/membership | F35: Project detail visitor | G35: P0 | H35: Visitor | I35: Public hiring/live/completed project exists | J35: Regression | R35: Core | S35: Not Run | U35: Retained
A36: Not Run | B36: GO-MAN-035 | C36: Projects | D36: Open private project URL as visitor/unrelated account | E36: Access is denied or redirected; private details are not visible | F36: Private project access | G36: P0 | H36: Visitor or unrelated user | I36: Private project exists | J36: Smoke | R36: Core | S36: Not Run | U36: Retained
A37: Not Run | B37: GO-MAN-036 | C37: Projects | D37: As a free user, open /project/create and choose the creator path. | E37: Membership guidance appears. No project is created. | F37: Free user creator-project gate | G37: P0 | H37: Free User | I37: Logged in without active company membership | J37: Regression | R37: Core | S37: Not Run | U37: Updated
A38: Not Run | B38: GO-MAN-037 | C38: Projects | D38: As an active Community member with no occupied slot, open /project/create, choose your own game, complete the wizard and submit. | E38: One draft creator project is saved. The member is not forced to buy Business for this path. | F38: Community creator-project allowance | G38: P0 | H38: Active Community member | I38: Use prepared QA records and separate accounts. Record the actual URL and build on Run Overview. No unreleased project in the capacity ledger. | J38: Smoke | R38: Core | S38: Not Run | U38: Updated
A39: Not Run | B39: GO-MAN-038 | C39: Projects | D39: As Business with agreed unused capacity, create a project and select a new source project. Refresh the creator workspace. | E39: One draft and one linked source record exist. Owner and team references are correct. | F39: Business creates project with new source | G39: P0 | H39: Company Subscriber | I39: Use prepared QA records and separate accounts. Record the actual URL and build on Run Overview. Business account has a positive agreed project limit. | J39: Smoke | R39: Core | S39: Retest | T39: V 1.7 TEST: I should not be able to select source projects from other projects that I am not the owner of or I haven't created as a company subscriber. I also as a company subscriber should be able to see the projects I have created as drafts under my projects and allow me to edit them even though they are only in draft and not approved by the admin. I also managed to create duplicates projects somehow, the project i created is called TEST 5 maybe you can use some info in the way it was created to help you or I will try to catch .har file. | U39: Updated
A40: Not Run | B40: GO-MAN-039 | C40: Projects | D40: As Business with an owned source and spare capacity, create a second project linked to that source. | E40: The saved project links to the chosen source. Another creator’s source cannot be selected. | F40: Business creates project with owned source | G40: P1 | H40: Company Subscriber | I40: Use prepared QA records and separate accounts. Record the actual URL and build on Run Overview. Business account has unused agreed capacity and an owned source. | J40: Regression | R40: Core | S40: Not Run | U40: Updated
...

Sheet UX Backlog
A2: UI, UX and motion backlog
A3: Capture observations during QA. Review prompts below are carried forward context, not newly verified defects.
A5: Item ID | B5: Area / Page | C5: Related Test / Source | D5: Type | E5: Observation | F5: Suggested change / decision | G5: Priority | H5: Status | I5: Evidence Link | J5: Owner | K5: Target round | L5: Acceptance check | M5: Reviewer decision | N5: Notes
A6: UX-001 | B6: Profile / Passport | C6: Known Issues #44 | D6: UX | E6: Prior note describes overlap between profile and Passport. | F6: Review purpose and navigation after the functional pass. | G6: P1 | H6: Review prompt | K6: After functional QA | L6: Distinct editing, learning and public-view destinations are understandable. | M6: Not reviewed | N6: Confirm current behavior before treating this as a defect.
A7: UX-002 | B7: Application rejection | C7: Known Issues #46 | D7: Product decision | E7: Prior request asks for rejection reasons and creator-controlled reapplication. | F7: Decide policy and message requirements before implementation. | G7: P1 | H7: Review prompt | K7: Future scope | L7: Approved behavior for reason, retry policy and status-change notice is documented. | M7: Not reviewed | N7: Current QA tests existing rejection only.
A8: UX-003 | B8: Avatar settings | C8: Known Issues #5 | D8: Product decision | E8: Generated/provider avatars exist. A prior request asks for custom upload/replacement. | F8: Decide supported avatar controls and storage requirements. | G8: P2 | H8: Review prompt | K8: Future scope | L8: Approved upload or generation behavior and limits are defined. | M8: Not reviewed
A9: UX-004 | B9: Motion baseline | C9: GO-MAN-673 | D9: Animation | E9: Capture existing motion before new animation work. | F9: Review baseline recordings and reduced-motion behavior. | G9: P2 | H9: Review prompt | K9: After functional QA | L9: Proposed motion has an equivalent reduced-motion state. | M9: Not reviewed | N9: This is a review task, not an observed animation defect.

Sheet V 1.8 TEST
A1: Status | B1: Test ID | C1: Suite | D1: Steps | E1: Expected Result | F1: Feature | G1: Priority | H1: Persona | I1: Preconditions | K1: Actual Result | L1: Notes | M1: Evidence Link | N1: Run Date
A2: Not Run | B2: GO-MAN-001 | C2: Public Website | D2: Open the home page; wait for the page to fully load; check above-the-fold content; scroll to bottom | E2: Home page loads without console-visible broken UI; main brand/content is clear; no missing critical images; footer is reachable | F2: Home page load | G2: P0 | H2: Visitor | I2: Production or local site is running
A3: Not Run | B3: GO-MAN-002 | C3: Public Website | D3: Open home page; click each main nav item; use browser back; repeat for logo/home link | E3: Every nav item routes to the expected page; no 404; active page content matches navigation label | F3: Desktop navigation | G3: P0 | H3: Visitor | I3: Site is running on desktop viewport
A4: Not Run | B4: GO-MAN-003 | C4: Public Website | D4: Resize to mobile or use phone; open mobile menu; tap every nav item; close and reopen menu | E4: Mobile menu is usable; links work; menu does not overlap content; menu can be dismissed | F4: Mobile navigation | G4: P0 | H4: Visitor | I4: Site is running on mobile viewport
A5: Not Run | B5: GO-MAN-004 | C5: Public Website | D5: Open home page; click primary CTA; return; click secondary CTAs; check destination pages | E5: CTAs route to intended signup/pricing/contact/project pages; labels match destination intent | F5: Landing CTAs | G5: P0 | H5: Visitor | I5: Site is running
A6: Not Run | B6: GO-MAN-005 | C6: Public Website | D6: Check home/pricing/projects/about/FAQ pages at 390px 768px and desktop widths | E6: No horizontal scrolling; text does not overlap; buttons fit; sections remain readable | F6: Responsive layout | G6: P1 | H6: Visitor | I6: Use desktop tablet and mobile widths
A7: Not Run | B7: GO-MAN-006 | C7: Public Website | D7: Open key public pages; look for broken images/icons; refresh once | E7: Images/icons render correctly; no obvious layout jumps due to missing assets | F7: Image and asset loading | G7: P1 | H7: Visitor | I7: Site is running
A8: Retest | B8: GO-MAN-007 | C8: Public Website | D8: Open FAQ; expand/collapse each FAQ item; check links if present | E8: FAQ controls work; content is readable; links open expected destinations | F8: FAQ page | G8: P1 | H8: Visitor | I8: FAQ page exists
A9: Retest | B9: GO-MAN-008 | C9: Public Website | D9: Open About; scan page content; test visible links/buttons | E9: About content is readable and current; links/buttons work; no typo-heavy or placeholder content | F9: About page | G9: P1 | H9: Visitor | I9: About page exists
A10: Not Run | B10: GO-MAN-009 | C10: Public Website | D10: Open pricing page; inspect all tiers and intervals; toggle monthly/annual if available | E10: Pricing is understandable; member vs company benefits are clear; checkout buttons are visible | F10: Pricing page | G10: P0 | H10: Visitor | I10: Polar products configured
A11: Not Run | B11: GO-MAN-010 | C11: Public Website | D11: Open a nonsense URL such as /this-page-does-not-exist | E11: User sees a graceful not-found or redirect experience; no raw error stack | F11: 404/not-found experience | G11: P2 | H11: Visitor | I11: Site is running
A12: Not Run | B12: GO-MAN-011 | C12: Auth | D12: Open signup; create account; complete required fields; submit | E12: Account is created; user lands on expected next page; no duplicate or confusing messages | F12: Signup flow | G12: P0 | H12: Visitor | I12: Test email available
A13: Not Run | B13: GO-MAN-012 | C13: Auth | D13: Open login; enter valid credentials; submit | E13: User logs in; protected nav/profile state appears; no unexpected redirect loop | F13: Login flow | G13: P0 | H13: Free User | I13: Existing account available
... A529: Not Run | B529: GO-MAN-528 | C529: Visual & Accessibility | D529: Using non-production data, open All new public, member, and administrator product surfaces. Prepare the state named “External-link indication”, perform the single relevant navigation or action, and record the visible result, resulting URL, HTTP status where applicable, and browser console/network errors. | E529: At “External-link indication”, content remains readable with no clipping or horizontal overflow; focus, labels, status meaning, touch targets, and motion behavior remain perceivable and operable. | F529: External-link indication | G529: P1 | H529: Visitor, keyboard user, screen-reader user, or administrator | I529: Use staging data for populated, empty, locked, loading, error, and confirmation states; reduced motion available. Use synthetic records and do not change production data.

Sheet  V 1.7 TEST
A1: Status | B1: Test ID | C1: Suite | D1: Steps | E1: Expected Result | F1: Feature | G1: Priority | H1: Persona | I1: Preconditions | K1: Actual Result | L1: Notes | M1: Evidence Link | N1: Run Date
A2: Not Run | B2: GO-MAN-001 | C2: Public Website | D2: Open the home page; wait for the page to fully load; check above-the-fold content; scroll to bottom | E2: Home page loads without console-visible broken UI; main brand/content is clear; no missing critical images; footer is reachable | F2: Home page load | G2: P0 | H2: Visitor | I2: Production or local site is running | K2: Functionally clean, however there are multiple improvements to be made on the Landing Page | L2: Bugs will be reported
A3: Not Run | B3: GO-MAN-002 | C3: Public Website | D3: Open home page; click each main nav item; use browser back; repeat for logo/home link | E3: Every nav item routes to the expected page; no 404; active page content matches navigation label | F3: Desktop navigation | G3: P0 | H3: Visitor | I3: Site is running on desktop viewport
A4: Not Run | B4: GO-MAN-003 | C4: Public Website | D4: Resize to mobile or use phone; open mobile menu; tap every nav item; close and reopen menu | E4: Mobile menu is usable; links work; menu does not overlap content; menu can be dismissed | F4: Mobile navigation | G4: P0 | H4: Visitor | I4: Site is running on mobile viewport
A5: Not Run | B5: GO-MAN-004 | C5: Public Website | D5: Open home page; click primary CTA; return; click secondary CTAs; check destination pages | E5: CTAs route to intended signup/pricing/contact/project pages; labels match destination intent | F5: Landing CTAs | G5: P0 | H5: Visitor | I5: Site is running
A6: Not Run | B6: GO-MAN-005 | C6: Public Website | D6: Check home/pricing/projects/about/FAQ pages at 390px 768px and desktop widths | E6: No horizontal scrolling; text does not overlap; buttons fit; sections remain readable | F6: Responsive layout | G6: P1 | H6: Visitor | I6: Use desktop tablet and mobile widths
A7: Not Run | B7: GO-MAN-006 | C7: Public Website | D7: Open key public pages; look for broken images/icons; refresh once | E7: Images/icons render correctly; no obvious layout jumps due to missing assets | F7: Image and asset loading | G7: P1 | H7: Visitor | I7: Site is running
A8: Retest | B8: GO-MAN-007 | C8: Public Website | D8: Open FAQ; expand/collapse each FAQ item; check links if present | E8: FAQ controls work; content is readable; links open expected destinations | F8: FAQ page | G8: P1 | H8: Visitor | I8: FAQ page exists | K8: Functionality is there but test is failed but the information is innacurate, we need to update the FAQ to reflect the real business proposition we are offering
A9: Retest | B9: GO-MAN-008 | C9: Public Website | D9: Open About; scan page content; test visible links/buttons | E9: About content is readable and current; links/buttons work; no typo-heavy or placeholder content | F9: About page | G9: P1 | H9: Visitor | I9: About page exists | K9: Functionality is there but test is failed but the information is innacurate, we need to update the ABOIT US to reflect the real business proposition we are offering
A10: Not Run | B10: GO-MAN-009 | C10: Public Website | D10: Open pricing page; inspect all tiers and intervals; toggle monthly/annual if available | E10: Pricing is understandable; member vs company benefits are clear; checkout buttons are visible | F10: Pricing page | G10: P0 | H10: Visitor | I10: Polar products configured | K10: We offer a community newsletter but we don't have one. See what we need in order to have one.
A11: Not Run | B11: GO-MAN-010 | C11: Public Website | D11: Open a nonsense URL such as /this-page-does-not-exist | E11: User sees a graceful not-found or redirect experience; no raw error stack | F11: 404/not-found experience | G11: P2 | H11: Visitor | I11: Site is running
A12: Not Run | B12: GO-MAN-011 | C12: Auth | D12: Open signup; create account; complete required fields; submit | E12: Account is created; user lands on expected next page; no duplicate or confusing messages | F12: Signup flow | G12: P0 | H12: Visitor | I12: Test email available
A13: Not Run | B13: GO-MAN-012 | C13: Auth | D13: Open login; enter valid credentials; submit | E13: User logs in; protected nav/profile state appears; no unexpected redirect loop | F13: Login flow | G13: P0 | H13: Free User | I13: Existing account available
A14: Not Run | B14: GO-MAN-013 | C14: Auth | D14: Enter invalid credentials; submit | E14: Clear error appears; password is not exposed; form remains usable | F14: Invalid login | G14: P1 | H14: Visitor | I14: Login page available
A15: Not Run | B15: GO-MAN-014 | C15: Auth | D15: Use profile/menu logout action; confirm logged-out state | E15: Session ends; protected links redirect or hide; public pages still work | F15: Logout flow | G15: P0 | H15: Logged-in User | I15: User is logged in
A16: Retest | B16: GO-MAN-015 | C16: Auth | D16: Open reset password; enter test account email; submit | E16: User receives success state; reset email is sent if email service is configured | F16: Password reset | G16: P1 | H16: Visitor | I16: Reset password page and email service configured | K16: Reset password throrws error Failed to send reset email. Please try again
A17: Not Run | B17: GO-MAN-016 | C17: Auth | D17: Open /dashboard /billing /admin /project/create directly | E17: Logged-out visitor is redirected or shown auth-required state; no protected data is visible | F17: Protected route redirect | G17: P0 | H17: Visitor | I17: Logged out
A18: Not Run | B18: GO-MAN-017 | C18: Auth | D18: Refresh current page; close and reopen browser tab; revisit site | E18: Session remains valid if expected; user identity and nav state are stable | F18: Session persistence | G18: P1 | H18: Logged-in User | I18: User is logged in
A19: Not Run | B19: GO-MAN-018 | C19: Onboarding | D19: Open onboarding page; begin onboarding flow | E19: Onboarding starts cleanly; first step is clear; progress is visible if expected | F19: Start onboarding | G19: P0 | H19: Logged-in User | I19: Logged in as member
A20: Not Run | B20: GO-MAN-019 | C20: Onboarding | D20: Complete every required onboarding step with valid values; submit final step | E20: Profile is saved; completion state appears; user can proceed to CV generation | F20: Complete required fields | G20: P0 | H20: Logged-in User | I20: Onboarding available
A21: Not Run | B21: GO-MAN-020 | C21: Onboarding | D21: Leave required fields empty; enter invalid URLs; exceed long text limits; submit | E21: Helpful validation errors appear; entered valid data is preserved; user can correct and continue | F21: Validation errors | G21: P1 | H21: Logged-in User | I21: Onboarding available
A22: Not Run | B22: GO-MAN-021 | C22: Onboarding | D22: Move forward several steps; go back; edit previous values; move forward again | E22: Previously entered values persist; progress remains correct; no data loss | F22: Back/forward navigation | G22: P1 | H22: Logged-in User | I22: Onboarding in progress
A23: Not Run | B23: GO-MAN-022 | C23: Onboarding | D23: Complete onboarding on mobile viewport | E23: Controls are tappable; inputs fit screen; progress and buttons remain visible | F23: Mobile onboarding | G23: P1 | H23: Logged-in User | I23: Mobile viewport
A24: Not Run | B24: GO-MAN-023 | C24: Profile | D24: Open profile page; inspect displayed fields | E24: Profile displays current user data; no private admin-only fields are shown | F24: View own profile | G24: P0 | H24: Logged-in User | I24: Profile data exists
A25: Not Run | B25: GO-MAN-024 | C25: Profile | D25: Edit display name role tools portfolio links and visibility settings; save | E25: Changes save successfully and persist after refresh | F25: Edit profile | G25: P0 | H25: Logged-in User | I25: Profile page available
A26: Not Run | B26: GO-MAN-025 | C26: Profile | D26: Enter social/portfolio URL without http/https; save | E26: Validation error appears; invalid URL is not silently accepted | F26: Profile invalid social URL | G26: P1 | H26: Logged-in User | I26: Profile editor available
A27: Not Run | B27: GO-MAN-026 | C27: Profile | D27: Toggle public/private or visibility settings; save; view from another account if possible | E27: Visibility settings persist and affect what other users can see | F27: Privacy settings | G27: P1 | H27: Logged-in User | I27: Profile editor available
A28: Not Run | B28: GO-MAN-027 | C28: CV | D28: Open CV page; click generate; wait for result | E28: CV is generated from profile data; title summary sections appear; no invented facts are obvious | F28: Generate CV | G28: P0 | H28: Logged-in User | I28: Onboarding profile completed
A29: Retest | B29: GO-MAN-028 | C29: CV | D29: Generate CV without AI service configured | E29: CV still generates with deterministic summary; user is not blocked by AI | F29: AI unavailable fallback | G29: P1 | H29: Logged-in User | I29: AI key disabled or unavailable in test env | K29: We will not be using AI for creation and updates of CV at the moment maybe in the future, all mentions for AI being used or consent formes need to be removed.
A30: Not Run | B30: GO-MAN-029 | C30: CV | D30: Edit CV title summary and at least one section; save | E30: Edits persist after refresh; formatting remains readable | F30: Edit CV | G30: P0 | H30: Logged-in User | I30: CV exists
A31: Not Run | B31: GO-MAN-030 | C31: CV | D31: Click publish/approve; confirm if prompted | E31: CV status becomes active/published; user receives clear success state | F31: Publish CV | G31: P0 | H31: Logged-in User | I31: Draft CV exists
A32: Not Run | B32: GO-MAN-031 | C32: CV | D32: Change CV visibility settings; view user/project application context from another account | E32: CV is visible only where expected based on settings | F32: CV visibility | G32: P1 | H32: Logged-in User | I32: CV exists and second account available
A33: Not Run | B33: GO-MAN-032 | C33: CV | D33: Open CV page; edit and publish on mobile | E33: CV editor and publish controls are usable; no clipped text/buttons | F33: CV mobile usability | G33: P1 | H33: Logged-in User | I33: Mobile viewport
A34: Not Run | B34: GO-MAN-033 | C34: Projects | D34: Open /projects while logged out; inspect visible projects | E34: Visitor sees only public discoverable projects; no private/draft/pending projects appear | F34: Project listing visitor | G34: P0 | H34: Visitor | I34: Projects exist with different statuses/visibility
A35: Not Run | B35: GO-MAN-034 | C35: Projects | D35: Open a public project detail page | E35: Project detail loads; visible fields are appropriate for visitor; apply controls require login/membership | F35: Project detail visitor | G35: P0 | H35: Visitor | I35: Public hiring/live/completed project exists
A36: Not Run | B36: GO-MAN-035 | C36: Projects | D36: Open private project URL as visitor/unrelated account | E36: Access is denied or redirected; private details are not visible | F36: Private project access | G36: P0 | H36: Visitor or unrelated user | I36: Private project exists
A37: Not Run | B37: GO-MAN-036 | C37: Projects | D37: Open /project/create; attempt project creation | E37: User is blocked with clear Company/Partner membership requirement | F37: Free user create block | G37: P0 | H37: Free User | I37: Logged in without active company membership
A38: Not Run | B38: GO-MAN-037 | C38: Projects | D38: Open /project/create; attempt project creation | E38: Member cannot create project; copy explains company tier requirement | F38: Member user create block | G38: P0 | H38: Member Subscriber | I38: Logged in with member tier only
A39: Retest | B39: GO-MAN-038 | C39: Projects | D39: Open /project/create; fill valid fields; choose new source project; submit | E39: Project is created as draft; source project is created; user becomes owner/admin/team member | F39: Company create project new source | G39: P0 | H39: Company Subscriber | I39: Company account active | K39: I should not be able to select source projects from other projects that I am not the owner of or I haven't created as a company subscriber. I also as a company subscriber should be able to see the projects I have created as drafts under my projects and allow me to edit them even though they are only in draft and not approved by the admin. I also managed to create duplicates projects somehow, the project i created is called TEST 5 maybe you can use some info in the way it was created to help you or I will try to catch .har file.
A40: Not Run | B40: GO-MAN-039 | C40: Projects | D40: Create another project using existing source project | E40: Project links to selected source project; source project project list updates | F40: Company create project existing source | G40: P1 | H40: Company Subscriber | I40: Company owns existing source project
...

Sheet V 1.6 TEST
A1: Status | B1: Test ID | C1: Suite | D1: Steps | E1: Expected Result | F1: Feature | G1: Priority | H1: Persona | I1: Preconditions | K1: Actual Result | L1: Notes | M1: Evidence Link | N1: Run Date
A2: Pass | B2: GO-MAN-001 | C2: Public Website | D2: Open the home page; wait for the page to fully load; check above-the-fold content; scroll to bottom | E2: Home page loads without console-visible broken UI; main brand/content is clear; no missing critical images; footer is reachable | F2: Home page load | G2: P0 | H2: Visitor | I2: Production or local site is running | K2: Functionally clean, however there are multiple improvements to be made on the Landing Page | L2: Bugs will be reported
A3: Pass | B3: GO-MAN-002 | C3: Public Website | D3: Open home page; click each main nav item; use browser back; repeat for logo/home link | E3: Every nav item routes to the expected page; no 404; active page content matches navigation label | F3: Desktop navigation | G3: P0 | H3: Visitor | I3: Site is running on desktop viewport
A4: Pass | B4: GO-MAN-003 | C4: Public Website | D4: Resize to mobile or use phone; open mobile menu; tap every nav item; close and reopen menu | E4: Mobile menu is usable; links work; menu does not overlap content; menu can be dismissed | F4: Mobile navigation | G4: P0 | H4: Visitor | I4: Site is running on mobile viewport
A5: Pass | B5: GO-MAN-004 | C5: Public Website | D5: Open home page; click primary CTA; return; click secondary CTAs; check destination pages | E5: CTAs route to intended signup/pricing/contact/project pages; labels match destination intent | F5: Landing CTAs | G5: P0 | H5: Visitor | I5: Site is running
A6: Pass | B6: GO-MAN-005 | C6: Public Website | D6: Check home/pricing/projects/about/FAQ pages at 390px 768px and desktop widths | E6: No horizontal scrolling; text does not overlap; buttons fit; sections remain readable | F6: Responsive layout | G6: P1 | H6: Visitor | I6: Use desktop tablet and mobile widths
A7: Pass | B7: GO-MAN-006 | C7: Public Website | D7: Open key public pages; look for broken images/icons; refresh once | E7: Images/icons render correctly; no obvious layout jumps due to missing assets | F7: Image and asset loading | G7: P1 | H7: Visitor | I7: Site is running
A8: Fail | B8: GO-MAN-007 | C8: Public Website | D8: Open FAQ; expand/collapse each FAQ item; check links if present | E8: FAQ controls work; content is readable; links open expected destinations | F8: FAQ page | G8: P1 | H8: Visitor | I8: FAQ page exists | K8: Functionality is there but test is failed but the information is innacurate, we need to update the FAQ to reflect the real business proposition we are offering
A9: Fail | B9: GO-MAN-008 | C9: Public Website | D9: Open About; scan page content; test visible links/buttons | E9: About content is readable and current; links/buttons work; no typo-heavy or placeholder content | F9: About page | G9: P1 | H9: Visitor | I9: About page exists | K9: Functionality is there but test is failed but the information is innacurate, we need to update the ABOIT US to reflect the real business proposition we are offering
A10: Pass | B10: GO-MAN-009 | C10: Public Website | D10: Open pricing page; inspect all tiers and intervals; toggle monthly/annual if available | E10: Pricing is understandable; member vs company benefits are clear; checkout buttons are visible | F10: Pricing page | G10: P0 | H10: Visitor | I10: Polar products configured | K10: We offer a community newsletter but we don't have one. See what we need in order to have one.
A11: Pass | B11: GO-MAN-010 | C11: Public Website | D11: Open a nonsense URL such as /this-page-does-not-exist | E11: User sees a graceful not-found or redirect experience; no raw error stack | F11: 404/not-found experience | G11: P2 | H11: Visitor | I11: Site is running
A12: Pass | B12: GO-MAN-011 | C12: Auth | D12: Open signup; create account; complete required fields; submit | E12: Account is created; user lands on expected next page; no duplicate or confusing messages | F12: Signup flow | G12: P0 | H12: Visitor | I12: Test email available
A13: Pass | B13: GO-MAN-012 | C13: Auth | D13: Open login; enter valid credentials; submit | E13: User logs in; protected nav/profile state appears; no unexpected redirect loop | F13: Login flow | G13: P0 | H13: Free User | I13: Existing account available
A14: Pass | B14: GO-MAN-013 | C14: Auth | D14: Enter invalid credentials; submit | E14: Clear error appears; password is not exposed; form remains usable | F14: Invalid login | G14: P1 | H14: Visitor | I14: Login page available
A15: Pass | B15: GO-MAN-014 | C15: Auth | D15: Use profile/menu logout action; confirm logged-out state | E15: Session ends; protected links redirect or hide; public pages still work | F15: Logout flow | G15: P0 | H15: Logged-in User | I15: User is logged in
A16: Fail | B16: GO-MAN-015 | C16: Auth | D16: Open reset password; enter test account email; submit | E16: User receives success state; reset email is sent if email service is configured | F16: Password reset | G16: P1 | H16: Visitor | I16: Reset password page and email service configured | K16: Reset password throrws error Failed to send reset email. Please try again
A17: Pass | B17: GO-MAN-016 | C17: Auth | D17: Open /dashboard /billing /admin /project/create directly | E17: Logged-out visitor is redirected or shown auth-required state; no protected data is visible | F17: Protected route redirect | G17: P0 | H17: Visitor | I17: Logged out
A18: Pass | B18: GO-MAN-017 | C18: Auth | D18: Refresh current page; close and reopen browser tab; revisit site | E18: Session remains valid if expected; user identity and nav state are stable | F18: Session persistence | G18: P1 | H18: Logged-in User | I18: User is logged in
A19: Pass | B19: GO-MAN-018 | C19: Onboarding | D19: Open onboarding page; begin onboarding flow | E19: Onboarding starts cleanly; first step is clear; progress is visible if expected | F19: Start onboarding | G19: P0 | H19: Logged-in User | I19: Logged in as member
A20: Pass | B20: GO-MAN-019 | C20: Onboarding | D20: Complete every required onboarding step with valid values; submit final step | E20: Profile is saved; completion state appears; user can proceed to CV generation | F20: Complete required fields | G20: P0 | H20: Logged-in User | I20: Onboarding available
A21: Pass | B21: GO-MAN-020 | C21: Onboarding | D21: Leave required fields empty; enter invalid URLs; exceed long text limits; submit | E21: Helpful validation errors appear; entered valid data is preserved; user can correct and continue | F21: Validation errors | G21: P1 | H21: Logged-in User | I21: Onboarding available
A22: Pass | B22: GO-MAN-021 | C22: Onboarding | D22: Move forward several steps; go back; edit previous values; move forward again | E22: Previously entered values persist; progress remains correct; no data loss | F22: Back/forward navigation | G22: P1 | H22: Logged-in User | I22: Onboarding in progress
A23: Pass | B23: GO-MAN-022 | C23: Onboarding | D23: Complete onboarding on mobile viewport | E23: Controls are tappable; inputs fit screen; progress and buttons remain visible | F23: Mobile onboarding | G23: P1 | H23: Logged-in User | I23: Mobile viewport
A24: Pass | B24: GO-MAN-023 | C24: Profile | D24: Open profile page; inspect displayed fields | E24: Profile displays current user data; no private admin-only fields are shown | F24: View own profile | G24: P0 | H24: Logged-in User | I24: Profile data exists
A25: Pass | B25: GO-MAN-024 | C25: Profile | D25: Edit display name role tools portfolio links and visibility settings; save | E25: Changes save successfully and persist after refresh | F25: Edit profile | G25: P0 | H25: Logged-in User | I25: Profile page available
A26: Pass | B26: GO-MAN-025 | C26: Profile | D26: Enter social/portfolio URL without http/https; save | E26: Validation error appears; invalid URL is not silently accepted | F26: Profile invalid social URL | G26: P1 | H26: Logged-in User | I26: Profile editor available
A27: Pass | B27: GO-MAN-026 | C27: Profile | D27: Toggle public/private or visibility settings; save; view from another account if possible | E27: Visibility settings persist and affect what other users can see | F27: Privacy settings | G27: P1 | H27: Logged-in User | I27: Profile editor available
A28: Pass | B28: GO-MAN-027 | C28: CV | D28: Open CV page; click generate; wait for result | E28: CV is generated from profile data; title summary sections appear; no invented facts are obvious | F28: Generate CV | G28: P0 | H28: Logged-in User | I28: Onboarding profile completed
A29: Fail | B29: GO-MAN-028 | C29: CV | D29: Generate CV without AI service configured | E29: CV still generates with deterministic summary; user is not blocked by AI | F29: AI unavailable fallback | G29: P1 | H29: Logged-in User | I29: AI key disabled or unavailable in test env | K29: We will not be using AI for creation and updates of CV at the moment maybe in the future, all mentions for AI being used or consent formes need to be removed.
A30: Pass | B30: GO-MAN-029 | C30: CV | D30: Edit CV title summary and at least one section; save | E30: Edits persist after refresh; formatting remains readable | F30: Edit CV | G30: P0 | H30: Logged-in User | I30: CV exists
A31: Pass | B31: GO-MAN-030 | C31: CV | D31: Click publish/approve; confirm if prompted | E31: CV status becomes active/published; user receives clear success state | F31: Publish CV | G31: P0 | H31: Logged-in User | I31: Draft CV exists
A32: Pass | B32: GO-MAN-031 | C32: CV | D32: Change CV visibility settings; view user/project application context from another account | E32: CV is visible only where expected based on settings | F32: CV visibility | G32: P1 | H32: Logged-in User | I32: CV exists and second account available
A33: Pass | B33: GO-MAN-032 | C33: CV | D33: Open CV page; edit and publish on mobile | E33: CV editor and publish controls are usable; no clipped text/buttons | F33: CV mobile usability | G33: P1 | H33: Logged-in User | I33: Mobile viewport
A34: Pass | B34: GO-MAN-033 | C34: Projects | D34: Open /projects while logged out; inspect visible projects | E34: Visitor sees only public discoverable projects; no private/draft/pending projects appear | F34: Project listing visitor | G34: P0 | H34: Visitor | I34: Projects exist with different statuses/visibility
A35: Pass | B35: GO-MAN-034 | C35: Projects | D35: Open a public project detail page | E35: Project detail loads; visible fields are appropriate for visitor; apply controls require login/membership | F35: Project detail visitor | G35: P0 | H35: Visitor | I35: Public hiring/live/completed project exists
A36: Pass | B36: GO-MAN-035 | C36: Projects | D36: Open private project URL as visitor/unrelated account | E36: Access is denied or redirected; private details are not visible | F36: Private project access | G36: P0 | H36: Visitor or unrelated user | I36: Private project exists
A37: Pass | B37: GO-MAN-036 | C37: Projects | D37: Open /project/create; attempt project creation | E37: User is blocked with clear Company/Partner membership requirement | F37: Free user create block | G37: P0 | H37: Free User | I37: Logged in without active company membership
A38: Pass | B38: GO-MAN-037 | C38: Projects | D38: Open /project/create; attempt project creation | E38: Member cannot create project; copy explains company tier requirement | F38: Member user create block | G38: P0 | H38: Member Subscriber | I38: Logged in with member tier only
A39: Fail | B39: GO-MAN-038 | C39: Projects | D39: Open /project/create; fill valid fields; choose new source project; submit | E39: Project is created as draft; source project is created; user becomes owner/admin/team member | F39: Company create project new source | G39: P0 | H39: Company Subscriber | I39: Company account active | K39: I should not be able to select source projects from other projects that I am not the owner of or I haven't created as a company subscriber. I also as a company subscriber should be able to see the projects I have created as drafts under my projects and allow me to edit them even though they are only in draft and not approved by the admin. I also managed to create duplicates projects somehow, the project i created is called TEST 5 maybe you can use some info in the way it was created to help you or I will try to catch .har file.
A40: Pass | B40: GO-MAN-039 | C40: Projects | D40: Create another project using existing source project | E40: Project links to selected source project; source project project list updates | F40: Company create project existing source | G40: P1 | H40: Company Subscriber | I40: Company owns existing source project
...

Sheet V 1.5 TEST
A1: Status | B1: Test ID | C1: Suite | D1: Feature | E1: Priority | F1: Persona | G1: Preconditions | H1: Steps | I1: Expected Result | J1: Actual Result | K1: Notes | L1: Evidence Link | M1: Run Date
A2: Retest | B2: GO-MAN-001 | C2: Public Website | D2: Home page load | E2: P0 | F2: Visitor | G2: Production or local site is running | H2: Open the home page; wait for the page to fully load; check above-the-fold content; scroll to bottom | I2: Home page loads without console-visible broken UI; main brand/content is clear; no missing critical images; footer is reachable | J2: Functionally clean, however there are multiple improvements to be made on the Landing Page | K2: Bugs will be reported
A3: Pass | B3: GO-MAN-002 | C3: Public Website | D3: Desktop navigation | E3: P0 | F3: Visitor | G3: Site is running on desktop viewport | H3: Open home page; click each main nav item; use browser back; repeat for logo/home link | I3: Every nav item routes to the expected page; no 404; active page content matches navigation label
A4: Pass | B4: GO-MAN-003 | C4: Public Website | D4: Mobile navigation | E4: P0 | F4: Visitor | G4: Site is running on mobile viewport | H4: Resize to mobile or use phone; open mobile menu; tap every nav item; close and reopen menu | I4: Mobile menu is usable; links work; menu does not overlap content; menu can be dismissed
A5: Pass | B5: GO-MAN-004 | C5: Public Website | D5: Landing CTAs | E5: P0 | F5: Visitor | G5: Site is running | H5: Open home page; click primary CTA; return; click secondary CTAs; check destination pages | I5: CTAs route to intended signup/pricing/contact/project pages; labels match destination intent
A6: Pass | B6: GO-MAN-005 | C6: Public Website | D6: Responsive layout | E6: P1 | F6: Visitor | G6: Use desktop tablet and mobile widths | H6: Check home/pricing/projects/about/FAQ pages at 390px 768px and desktop widths | I6: No horizontal scrolling; text does not overlap; buttons fit; sections remain readable
A7: Pass | B7: GO-MAN-006 | C7: Public Website | D7: Image and asset loading | E7: P1 | F7: Visitor | G7: Site is running | H7: Open key public pages; look for broken images/icons; refresh once | I7: Images/icons render correctly; no obvious layout jumps due to missing assets
